using System;
using System.Collections.Generic;
using System.Linq;
using System.Text;
using System.Threading.Tasks;

namespace ByteBank
{
    class Program
    {
        static void Main(string[] args)
        {
            try
            {
                ContaCorrente conta = new ContaCorrente(456, 0);
            }
            catch (ArgumentException ex)
            {
                if (ex.ParamName == "numero")
                {

                }

                Console.WriteLine("Argumento com problema: " + ex.ParamName);
                Console.WriteLine("Ocorreu uma exceção do tipo ArgumentException");
                Console.WriteLine(ex.Message);
            }
            catch (Exception ex)
            {
                Console.WriteLine(ex.Message);
            }

            // Metodo();

            Console.WriteLine("Execução finalizada. Tecle enter para sair");
            Console.ReadLine();
        }

        // Teste com a cadeia de chamada:
        // Metodo -> TestaDivisao -> Dividir
        static void Metodo()
        {
            TestaDivisao(0);
        }

        static void TestaDivisao(int divisor)
        {
            try
            {
                Dividir(10, divisor);
            }
            catch (NullReferenceException ex)
            {
                Console.WriteLine("Fui capturado pelo (NullReferenceException ex)");
                Console.WriteLine(ex.StackTrace);
            }
            catch (Exception ex)
            {
                Console.WriteLine("Fui capturado pelo (Exception ex)");
                Console.WriteLine(ex.StackTrace);
            }

            Console.WriteLine("Estou executando normalmente!");
        }

        public static int Dividir(int numero, int divisor)
        {
            try
            {
                Console.WriteLine("Fazendo o cálculo " + numero + " / " + divisor);
                int resultado = numero / divisor;
                Console.WriteLine("O resultado é " + resultado);
                return resultado;
            }
            catch (Exception ex)
            {
                Console.WriteLine("Erro no cálculo: " + ex.Message);
                throw; // Lançar exceção

                Console.WriteLine("Depois do throw");
            }
        }
    }
}
